8/25/2021 12:02:15 PM
Create
------------------------------
System.AggregateException: One or more errors occurred. ---> System.AggregateException: One or more errors occurred. ---> System.Net.Http.HttpRequestException: An error occurred while sending the request. ---> System.Net.WebException: The underlying connection was closed: An unexpected error occurred on a receive. ---> System.IO.IOException: Unable to read data from the transport connection: An existing connection was forcibly closed by the remote host. ---> System.Net.Sockets.SocketException: An existing connection was forcibly closed by the remote host
   at System.Net.Sockets.Socket.EndReceive(IAsyncResult asyncResult)
   at System.Net.Sockets.NetworkStream.EndRead(IAsyncResult asyncResult)
   --- End of inner exception stack trace ---
   at System.Net.Sockets.NetworkStream.EndRead(IAsyncResult asyncResult)
   at System.Net.PooledStream.EndRead(IAsyncResult asyncResult)
   at System.Net.Connection.ReadCallback(IAsyncResult asyncResult)
   --- End of inner exception stack trace ---
   at System.Net.HttpWebRequest.EndGetResponse(IAsyncResult asyncResult)
   at System.Net.Http.HttpClientHandler.GetResponseCallback(IAsyncResult ar)
   --- End of inner exception stack trace ---
   --- End of inner exception stack trace ---
   at System.Threading.Tasks.Task.ThrowIfExceptional(Boolean includeTaskCanceledExceptions)
   at System.Threading.Tasks.Task`1.GetResultCore(Boolean waitCompletionNotification)
   at System.Threading.Tasks.Task`1.get_Result()
   at HBL_MLDV_APP.Repository.UniversalRepository.<SaveData>d__14.MoveNext() in E:\Naveel\GIT_PROJECTS\HBL_MLDV_APP\HBL_MLDV_APP\Repository\UniversalRepository.cs:line 131
   --- End of inner exception stack trace ---
   at System.Threading.Tasks.Task.ThrowIfExceptional(Boolean includeTaskCanceledExceptions)
   at System.Threading.Tasks.Task`1.GetResultCore(Boolean waitCompletionNotification)
   at System.Threading.Tasks.Task`1.get_Result()
   at HBL_MLDV_APP.Areas.UserManagement.Controllers.UserController.<Create>d__6.MoveNext() in E:\Naveel\GIT_PROJECTS\HBL_MLDV_APP\HBL_MLDV_APP\Areas\UserManagement\Controllers\UserController.cs:line 138
---> (Inner Exception #0) System.AggregateException: One or more errors occurred. ---> System.Net.Http.HttpRequestException: An error occurred while sending the request. ---> System.Net.WebException: The underlying connection was closed: An unexpected error occurred on a receive. ---> System.IO.IOException: Unable to read data from the transport connection: An existing connection was forcibly closed by the remote host. ---> System.Net.Sockets.SocketException: An existing connection was forcibly closed by the remote host
   at System.Net.Sockets.Socket.EndReceive(IAsyncResult asyncResult)
   at System.Net.Sockets.NetworkStream.EndRead(IAsyncResult asyncResult)
   --- End of inner exception stack trace ---
   at System.Net.Sockets.NetworkStream.EndRead(IAsyncResult asyncResult)
   at System.Net.PooledStream.EndRead(IAsyncResult asyncResult)
   at System.Net.Connection.ReadCallback(IAsyncResult asyncResult)
   --- End of inner exception stack trace ---
   at System.Net.HttpWebRequest.EndGetResponse(IAsyncResult asyncResult)
   at System.Net.Http.HttpClientHandler.GetResponseCallback(IAsyncResult ar)
   --- End of inner exception stack trace ---
   --- End of inner exception stack trace ---
   at System.Threading.Tasks.Task.ThrowIfExceptional(Boolean includeTaskCanceledExceptions)
   at System.Threading.Tasks.Task`1.GetResultCore(Boolean waitCompletionNotification)
   at System.Threading.Tasks.Task`1.get_Result()
   at HBL_MLDV_APP.Repository.UniversalRepository.<SaveData>d__14.MoveNext() in E:\Naveel\GIT_PROJECTS\HBL_MLDV_APP\HBL_MLDV_APP\Repository\UniversalRepository.cs:line 131
---> (Inner Exception #0) System.Net.Http.HttpRequestException: An error occurred while sending the request. ---> System.Net.WebException: The underlying connection was closed: An unexpected error occurred on a receive. ---> System.IO.IOException: Unable to read data from the transport connection: An existing connection was forcibly closed by the remote host. ---> System.Net.Sockets.SocketException: An existing connection was forcibly closed by the remote host
   at System.Net.Sockets.Socket.EndReceive(IAsyncResult asyncResult)
   at System.Net.Sockets.NetworkStream.EndRead(IAsyncResult asyncResult)
   --- End of inner exception stack trace ---
   at System.Net.Sockets.NetworkStream.EndRead(IAsyncResult asyncResult)
   at System.Net.PooledStream.EndRead(IAsyncResult asyncResult)
   at System.Net.Connection.ReadCallback(IAsyncResult asyncResult)
   --- End of inner exception stack trace ---
   at System.Net.HttpWebRequest.EndGetResponse(IAsyncResult asyncResult)
   at System.Net.Http.HttpClientHandler.GetResponseCallback(IAsyncResult ar)
   --- End of inner exception stack trace ---<---
<---

------------------------------
8/25/2021 4:40:31 PM
Edit
------------------------------
System.AggregateException: One or more errors occurred. ---> System.AggregateException: One or more errors occurred. ---> System.Threading.Tasks.TaskCanceledException: A task was canceled.
   --- End of inner exception stack trace ---
   at System.Threading.Tasks.Task.ThrowIfExceptional(Boolean includeTaskCanceledExceptions)
   at System.Threading.Tasks.Task`1.GetResultCore(Boolean waitCompletionNotification)
   at System.Threading.Tasks.Task`1.get_Result()
   at HBL_MLDV_APP.Repository.UniversalRepository.<SaveData>d__14.MoveNext()
   --- End of inner exception stack trace ---
   at System.Threading.Tasks.Task.ThrowIfExceptional(Boolean includeTaskCanceledExceptions)
   at System.Threading.Tasks.Task`1.GetResultCore(Boolean waitCompletionNotification)
   at System.Threading.Tasks.Task`1.get_Result()
   at HBL_MLDV_APP.Areas.UserManagement.Controllers.UserController.<Edit>d__9.MoveNext()
---> (Inner Exception #0) System.AggregateException: One or more errors occurred. ---> System.Threading.Tasks.TaskCanceledException: A task was canceled.
   --- End of inner exception stack trace ---
   at System.Threading.Tasks.Task.ThrowIfExceptional(Boolean includeTaskCanceledExceptions)
   at System.Threading.Tasks.Task`1.GetResultCore(Boolean waitCompletionNotification)
   at System.Threading.Tasks.Task`1.get_Result()
   at HBL_MLDV_APP.Repository.UniversalRepository.<SaveData>d__14.MoveNext()
---> (Inner Exception #0) System.Threading.Tasks.TaskCanceledException: A task was canceled.<---
<---

------------------------------
8/25/2021 4:58:01 PM
Edit
------------------------------
System.AggregateException: One or more errors occurred. ---> System.AggregateException: One or more errors occurred. ---> System.Threading.Tasks.TaskCanceledException: A task was canceled.
   --- End of inner exception stack trace ---
   at System.Threading.Tasks.Task.ThrowIfExceptional(Boolean includeTaskCanceledExceptions)
   at System.Threading.Tasks.Task`1.GetResultCore(Boolean waitCompletionNotification)
   at System.Threading.Tasks.Task`1.get_Result()
   at HBL_MLDV_APP.Repository.UniversalRepository.<SaveData>d__14.MoveNext()
   --- End of inner exception stack trace ---
   at System.Threading.Tasks.Task.ThrowIfExceptional(Boolean includeTaskCanceledExceptions)
   at System.Threading.Tasks.Task`1.GetResultCore(Boolean waitCompletionNotification)
   at System.Threading.Tasks.Task`1.get_Result()
   at HBL_MLDV_APP.Areas.UserManagement.Controllers.UserController.<Edit>d__9.MoveNext()
---> (Inner Exception #0) System.AggregateException: One or more errors occurred. ---> System.Threading.Tasks.TaskCanceledException: A task was canceled.
   --- End of inner exception stack trace ---
   at System.Threading.Tasks.Task.ThrowIfExceptional(Boolean includeTaskCanceledExceptions)
   at System.Threading.Tasks.Task`1.GetResultCore(Boolean waitCompletionNotification)
   at System.Threading.Tasks.Task`1.get_Result()
   at HBL_MLDV_APP.Repository.UniversalRepository.<SaveData>d__14.MoveNext()
---> (Inner Exception #0) System.Threading.Tasks.TaskCanceledException: A task was canceled.<---
<---

------------------------------
8/25/2021 4:59:48 PM
Edit
------------------------------
System.AggregateException: One or more errors occurred. ---> System.AggregateException: One or more errors occurred. ---> System.Threading.Tasks.TaskCanceledException: A task was canceled.
   --- End of inner exception stack trace ---
   at System.Threading.Tasks.Task.ThrowIfExceptional(Boolean includeTaskCanceledExceptions)
   at System.Threading.Tasks.Task`1.GetResultCore(Boolean waitCompletionNotification)
   at System.Threading.Tasks.Task`1.get_Result()
   at HBL_MLDV_APP.Repository.UniversalRepository.<SaveData>d__14.MoveNext()
   --- End of inner exception stack trace ---
   at System.Threading.Tasks.Task.ThrowIfExceptional(Boolean includeTaskCanceledExceptions)
   at System.Threading.Tasks.Task`1.GetResultCore(Boolean waitCompletionNotification)
   at System.Threading.Tasks.Task`1.get_Result()
   at HBL_MLDV_APP.Areas.UserManagement.Controllers.UserController.<Edit>d__9.MoveNext()
---> (Inner Exception #0) System.AggregateException: One or more errors occurred. ---> System.Threading.Tasks.TaskCanceledException: A task was canceled.
   --- End of inner exception stack trace ---
   at System.Threading.Tasks.Task.ThrowIfExceptional(Boolean includeTaskCanceledExceptions)
   at System.Threading.Tasks.Task`1.GetResultCore(Boolean waitCompletionNotification)
   at System.Threading.Tasks.Task`1.get_Result()
   at HBL_MLDV_APP.Repository.UniversalRepository.<SaveData>d__14.MoveNext()
---> (Inner Exception #0) System.Threading.Tasks.TaskCanceledException: A task was canceled.<---
<---

------------------------------
8/25/2021 5:10:53 PM
Edit
------------------------------
System.AggregateException: One or more errors occurred. ---> System.AggregateException: One or more errors occurred. ---> System.Threading.Tasks.TaskCanceledException: A task was canceled.
   --- End of inner exception stack trace ---
   at System.Threading.Tasks.Task.ThrowIfExceptional(Boolean includeTaskCanceledExceptions)
   at System.Threading.Tasks.Task`1.GetResultCore(Boolean waitCompletionNotification)
   at System.Threading.Tasks.Task`1.get_Result()
   at HBL_MLDV_APP.Repository.UniversalRepository.<SaveData>d__14.MoveNext()
   --- End of inner exception stack trace ---
   at System.Threading.Tasks.Task.ThrowIfExceptional(Boolean includeTaskCanceledExceptions)
   at System.Threading.Tasks.Task`1.GetResultCore(Boolean waitCompletionNotification)
   at System.Threading.Tasks.Task`1.get_Result()
   at HBL_MLDV_APP.Areas.UserManagement.Controllers.UserController.<Edit>d__9.MoveNext()
---> (Inner Exception #0) System.AggregateException: One or more errors occurred. ---> System.Threading.Tasks.TaskCanceledException: A task was canceled.
   --- End of inner exception stack trace ---
   at System.Threading.Tasks.Task.ThrowIfExceptional(Boolean includeTaskCanceledExceptions)
   at System.Threading.Tasks.Task`1.GetResultCore(Boolean waitCompletionNotification)
   at System.Threading.Tasks.Task`1.get_Result()
   at HBL_MLDV_APP.Repository.UniversalRepository.<SaveData>d__14.MoveNext()
---> (Inner Exception #0) System.Threading.Tasks.TaskCanceledException: A task was canceled.<---
<---

------------------------------
8/25/2021 5:33:36 PM
Edit
------------------------------
System.AggregateException: One or more errors occurred. ---> System.AggregateException: One or more errors occurred. ---> System.Threading.Tasks.TaskCanceledException: A task was canceled.
   --- End of inner exception stack trace ---
   at System.Threading.Tasks.Task.ThrowIfExceptional(Boolean includeTaskCanceledExceptions)
   at System.Threading.Tasks.Task`1.GetResultCore(Boolean waitCompletionNotification)
   at System.Threading.Tasks.Task`1.get_Result()
   at HBL_MLDV_APP.Repository.UniversalRepository.<SaveData>d__14.MoveNext()
   --- End of inner exception stack trace ---
   at System.Threading.Tasks.Task.ThrowIfExceptional(Boolean includeTaskCanceledExceptions)
   at System.Threading.Tasks.Task`1.GetResultCore(Boolean waitCompletionNotification)
   at System.Threading.Tasks.Task`1.get_Result()
   at HBL_MLDV_APP.Areas.UserManagement.Controllers.UserController.<Edit>d__9.MoveNext()
---> (Inner Exception #0) System.AggregateException: One or more errors occurred. ---> System.Threading.Tasks.TaskCanceledException: A task was canceled.
   --- End of inner exception stack trace ---
   at System.Threading.Tasks.Task.ThrowIfExceptional(Boolean includeTaskCanceledExceptions)
   at System.Threading.Tasks.Task`1.GetResultCore(Boolean waitCompletionNotification)
   at System.Threading.Tasks.Task`1.get_Result()
   at HBL_MLDV_APP.Repository.UniversalRepository.<SaveData>d__14.MoveNext()
---> (Inner Exception #0) System.Threading.Tasks.TaskCanceledException: A task was canceled.<---
<---

------------------------------
