8/25/2021 12:07:53 PM
Edit
------------------------------
System.ArgumentNullException: Value cannot be null.
Parameter name: source
   at System.Linq.Enumerable.Where[TSource](IEnumerable`1 source, Func`2 predicate)
   at HBL_MLDV_APP.Areas.UserManagement.Controllers.UserController.<Edit>d__8.MoveNext() in E:\Naveel\GIT_PROJECTS\HBL_MLDV_APP\HBL_MLDV_APP\Areas\UserManagement\Controllers\UserController.cs:line 250
------------------------------
8/25/2021 12:07:55 PM
Edit
------------------------------
System.ArgumentNullException: Value cannot be null.
Parameter name: source
   at System.Linq.Enumerable.Where[TSource](IEnumerable`1 source, Func`2 predicate)
   at HBL_MLDV_APP.Areas.UserManagement.Controllers.UserController.<Edit>d__8.MoveNext() in E:\Naveel\GIT_PROJECTS\HBL_MLDV_APP\HBL_MLDV_APP\Areas\UserManagement\Controllers\UserController.cs:line 250
------------------------------
8/25/2021 3:00:08 PM
Edit
------------------------------
System.AggregateException: One or more errors occurred. ---> System.AggregateException: One or more errors occurred. ---> System.Threading.Tasks.TaskCanceledException: A task was canceled.
   --- End of inner exception stack trace ---
   at System.Threading.Tasks.Task.ThrowIfExceptional(Boolean includeTaskCanceledExceptions)
   at System.Threading.Tasks.Task`1.GetResultCore(Boolean waitCompletionNotification)
   at System.Threading.Tasks.Task`1.get_Result()
   at HBL_MLDV_APP.Repository.UniversalRepository.<GetData>d__11.MoveNext() in E:\Naveel\GIT_PROJECTS\HBL_MLDV_APP\HBL_MLDV_APP\Repository\UniversalRepository.cs:line 88
   --- End of inner exception stack trace ---
   at System.Threading.Tasks.Task.ThrowIfExceptional(Boolean includeTaskCanceledExceptions)
   at System.Threading.Tasks.Task`1.GetResultCore(Boolean waitCompletionNotification)
   at System.Threading.Tasks.Task`1.get_Result()
   at HBL_MLDV_APP.Areas.UserManagement.Controllers.UserController.<GetUserAprvById>d__20.MoveNext() in E:\Naveel\GIT_PROJECTS\HBL_MLDV_APP\HBL_MLDV_APP\Areas\UserManagement\Controllers\UserController.cs:line 674
--- End of stack trace from previous location where exception was thrown ---
   at System.Runtime.CompilerServices.TaskAwaiter.ThrowForNonSuccess(Task task)
   at System.Runtime.CompilerServices.TaskAwaiter.HandleNonSuccessAndDebuggerNotification(Task task)
   at System.Runtime.CompilerServices.TaskAwaiter`1.GetResult()
   at HBL_MLDV_APP.Areas.UserManagement.Controllers.UserController.<Edit>d__8.MoveNext() in E:\Naveel\GIT_PROJECTS\HBL_MLDV_APP\HBL_MLDV_APP\Areas\UserManagement\Controllers\UserController.cs:line 243
---> (Inner Exception #0) System.AggregateException: One or more errors occurred. ---> System.Threading.Tasks.TaskCanceledException: A task was canceled.
   --- End of inner exception stack trace ---
   at System.Threading.Tasks.Task.ThrowIfExceptional(Boolean includeTaskCanceledExceptions)
   at System.Threading.Tasks.Task`1.GetResultCore(Boolean waitCompletionNotification)
   at System.Threading.Tasks.Task`1.get_Result()
   at HBL_MLDV_APP.Repository.UniversalRepository.<GetData>d__11.MoveNext() in E:\Naveel\GIT_PROJECTS\HBL_MLDV_APP\HBL_MLDV_APP\Repository\UniversalRepository.cs:line 88
---> (Inner Exception #0) System.Threading.Tasks.TaskCanceledException: A task was canceled.<---
<---

------------------------------
8/25/2021 3:01:25 PM
Edit
------------------------------
System.AggregateException: One or more errors occurred. ---> System.AggregateException: One or more errors occurred. ---> System.Net.Http.HttpRequestException: An error occurred while sending the request. ---> System.Net.WebException: Unable to connect to the remote server ---> System.Net.Sockets.SocketException: No connection could be made because the target machine actively refused it 127.0.0.1:61657
   at System.Net.Sockets.Socket.InternalEndConnect(IAsyncResult asyncResult)
   at System.Net.Sockets.Socket.EndConnect(IAsyncResult asyncResult)
   at System.Net.ServicePoint.ConnectSocketInternal(Boolean connectFailure, Socket s4, Socket s6, Socket& socket, IPAddress& address, ConnectSocketState state, IAsyncResult asyncResult, Exception& exception)
   --- End of inner exception stack trace ---
   at System.Net.HttpWebRequest.EndGetResponse(IAsyncResult asyncResult)
   at System.Net.Http.HttpClientHandler.GetResponseCallback(IAsyncResult ar)
   --- End of inner exception stack trace ---
   --- End of inner exception stack trace ---
   at System.Threading.Tasks.Task.ThrowIfExceptional(Boolean includeTaskCanceledExceptions)
   at System.Threading.Tasks.Task`1.GetResultCore(Boolean waitCompletionNotification)
   at System.Threading.Tasks.Task`1.get_Result()
   at HBL_MLDV_APP.Repository.UniversalRepository.<GetData>d__11.MoveNext() in E:\Naveel\GIT_PROJECTS\HBL_MLDV_APP\HBL_MLDV_APP\Repository\UniversalRepository.cs:line 88
   --- End of inner exception stack trace ---
   at System.Threading.Tasks.Task.ThrowIfExceptional(Boolean includeTaskCanceledExceptions)
   at System.Threading.Tasks.Task`1.GetResultCore(Boolean waitCompletionNotification)
   at System.Threading.Tasks.Task`1.get_Result()
   at HBL_MLDV_APP.Areas.UserManagement.Controllers.UserController.<GetUserAprvById>d__20.MoveNext() in E:\Naveel\GIT_PROJECTS\HBL_MLDV_APP\HBL_MLDV_APP\Areas\UserManagement\Controllers\UserController.cs:line 674
--- End of stack trace from previous location where exception was thrown ---
   at System.Runtime.CompilerServices.TaskAwaiter.ThrowForNonSuccess(Task task)
   at System.Runtime.CompilerServices.TaskAwaiter.HandleNonSuccessAndDebuggerNotification(Task task)
   at System.Runtime.CompilerServices.TaskAwaiter`1.GetResult()
   at HBL_MLDV_APP.Areas.UserManagement.Controllers.UserController.<Edit>d__8.MoveNext() in E:\Naveel\GIT_PROJECTS\HBL_MLDV_APP\HBL_MLDV_APP\Areas\UserManagement\Controllers\UserController.cs:line 243
---> (Inner Exception #0) System.AggregateException: One or more errors occurred. ---> System.Net.Http.HttpRequestException: An error occurred while sending the request. ---> System.Net.WebException: Unable to connect to the remote server ---> System.Net.Sockets.SocketException: No connection could be made because the target machine actively refused it 127.0.0.1:61657
   at System.Net.Sockets.Socket.InternalEndConnect(IAsyncResult asyncResult)
   at System.Net.Sockets.Socket.EndConnect(IAsyncResult asyncResult)
   at System.Net.ServicePoint.ConnectSocketInternal(Boolean connectFailure, Socket s4, Socket s6, Socket& socket, IPAddress& address, ConnectSocketState state, IAsyncResult asyncResult, Exception& exception)
   --- End of inner exception stack trace ---
   at System.Net.HttpWebRequest.EndGetResponse(IAsyncResult asyncResult)
   at System.Net.Http.HttpClientHandler.GetResponseCallback(IAsyncResult ar)
   --- End of inner exception stack trace ---
   --- End of inner exception stack trace ---
   at System.Threading.Tasks.Task.ThrowIfExceptional(Boolean includeTaskCanceledExceptions)
   at System.Threading.Tasks.Task`1.GetResultCore(Boolean waitCompletionNotification)
   at System.Threading.Tasks.Task`1.get_Result()
   at HBL_MLDV_APP.Repository.UniversalRepository.<GetData>d__11.MoveNext() in E:\Naveel\GIT_PROJECTS\HBL_MLDV_APP\HBL_MLDV_APP\Repository\UniversalRepository.cs:line 88
---> (Inner Exception #0) System.Net.Http.HttpRequestException: An error occurred while sending the request. ---> System.Net.WebException: Unable to connect to the remote server ---> System.Net.Sockets.SocketException: No connection could be made because the target machine actively refused it 127.0.0.1:61657
   at System.Net.Sockets.Socket.InternalEndConnect(IAsyncResult asyncResult)
   at System.Net.Sockets.Socket.EndConnect(IAsyncResult asyncResult)
   at System.Net.ServicePoint.ConnectSocketInternal(Boolean connectFailure, Socket s4, Socket s6, Socket& socket, IPAddress& address, ConnectSocketState state, IAsyncResult asyncResult, Exception& exception)
   --- End of inner exception stack trace ---
   at System.Net.HttpWebRequest.EndGetResponse(IAsyncResult asyncResult)
   at System.Net.Http.HttpClientHandler.GetResponseCallback(IAsyncResult ar)
   --- End of inner exception stack trace ---<---
<---

------------------------------
8/25/2021 3:04:05 PM
Edit
------------------------------
System.AggregateException: One or more errors occurred. ---> System.AggregateException: One or more errors occurred. ---> System.Threading.Tasks.TaskCanceledException: A task was canceled.
   --- End of inner exception stack trace ---
   at System.Threading.Tasks.Task.ThrowIfExceptional(Boolean includeTaskCanceledExceptions)
   at System.Threading.Tasks.Task`1.GetResultCore(Boolean waitCompletionNotification)
   at System.Threading.Tasks.Task`1.get_Result()
   at HBL_MLDV_APP.Repository.UniversalRepository.<GetData>d__11.MoveNext() in E:\Naveel\GIT_PROJECTS\HBL_MLDV_APP\HBL_MLDV_APP\Repository\UniversalRepository.cs:line 88
   --- End of inner exception stack trace ---
   at System.Threading.Tasks.Task.ThrowIfExceptional(Boolean includeTaskCanceledExceptions)
   at System.Threading.Tasks.Task`1.GetResultCore(Boolean waitCompletionNotification)
   at System.Threading.Tasks.Task`1.get_Result()
   at HBL_MLDV_APP.Areas.UserManagement.Controllers.UserController.<GetUserAprvById>d__20.MoveNext() in E:\Naveel\GIT_PROJECTS\HBL_MLDV_APP\HBL_MLDV_APP\Areas\UserManagement\Controllers\UserController.cs:line 674
--- End of stack trace from previous location where exception was thrown ---
   at System.Runtime.CompilerServices.TaskAwaiter.ThrowForNonSuccess(Task task)
   at System.Runtime.CompilerServices.TaskAwaiter.HandleNonSuccessAndDebuggerNotification(Task task)
   at System.Runtime.CompilerServices.TaskAwaiter`1.GetResult()
   at HBL_MLDV_APP.Areas.UserManagement.Controllers.UserController.<Edit>d__8.MoveNext() in E:\Naveel\GIT_PROJECTS\HBL_MLDV_APP\HBL_MLDV_APP\Areas\UserManagement\Controllers\UserController.cs:line 243
---> (Inner Exception #0) System.AggregateException: One or more errors occurred. ---> System.Threading.Tasks.TaskCanceledException: A task was canceled.
   --- End of inner exception stack trace ---
   at System.Threading.Tasks.Task.ThrowIfExceptional(Boolean includeTaskCanceledExceptions)
   at System.Threading.Tasks.Task`1.GetResultCore(Boolean waitCompletionNotification)
   at System.Threading.Tasks.Task`1.get_Result()
   at HBL_MLDV_APP.Repository.UniversalRepository.<GetData>d__11.MoveNext() in E:\Naveel\GIT_PROJECTS\HBL_MLDV_APP\HBL_MLDV_APP\Repository\UniversalRepository.cs:line 88
---> (Inner Exception #0) System.Threading.Tasks.TaskCanceledException: A task was canceled.<---
<---

------------------------------
8/25/2021 3:05:06 PM
Edit
------------------------------
System.NullReferenceException: Object reference not set to an instance of an object.
   at HBL_MLDV_APP.Areas.UserManagement.Controllers.UserController.<Edit>d__8.MoveNext() in E:\Naveel\GIT_PROJECTS\HBL_MLDV_APP\HBL_MLDV_APP\Areas\UserManagement\Controllers\UserController.cs:line 250
------------------------------
8/25/2021 3:06:51 PM
Edit
------------------------------
System.AggregateException: One or more errors occurred. ---> System.AggregateException: One or more errors occurred. ---> System.Threading.Tasks.TaskCanceledException: A task was canceled.
   --- End of inner exception stack trace ---
   at System.Threading.Tasks.Task.ThrowIfExceptional(Boolean includeTaskCanceledExceptions)
   at System.Threading.Tasks.Task`1.GetResultCore(Boolean waitCompletionNotification)
   at System.Threading.Tasks.Task`1.get_Result()
   at HBL_MLDV_APP.Repository.UniversalRepository.<GetData>d__11.MoveNext() in E:\Naveel\GIT_PROJECTS\HBL_MLDV_APP\HBL_MLDV_APP\Repository\UniversalRepository.cs:line 88
   --- End of inner exception stack trace ---
   at System.Threading.Tasks.Task.ThrowIfExceptional(Boolean includeTaskCanceledExceptions)
   at System.Threading.Tasks.Task`1.GetResultCore(Boolean waitCompletionNotification)
   at System.Threading.Tasks.Task`1.get_Result()
   at HBL_MLDV_APP.Areas.UserManagement.Controllers.UserController.<GetUserAprvById>d__20.MoveNext() in E:\Naveel\GIT_PROJECTS\HBL_MLDV_APP\HBL_MLDV_APP\Areas\UserManagement\Controllers\UserController.cs:line 674
--- End of stack trace from previous location where exception was thrown ---
   at System.Runtime.CompilerServices.TaskAwaiter.ThrowForNonSuccess(Task task)
   at System.Runtime.CompilerServices.TaskAwaiter.HandleNonSuccessAndDebuggerNotification(Task task)
   at System.Runtime.CompilerServices.TaskAwaiter`1.GetResult()
   at HBL_MLDV_APP.Areas.UserManagement.Controllers.UserController.<Edit>d__8.MoveNext() in E:\Naveel\GIT_PROJECTS\HBL_MLDV_APP\HBL_MLDV_APP\Areas\UserManagement\Controllers\UserController.cs:line 243
---> (Inner Exception #0) System.AggregateException: One or more errors occurred. ---> System.Threading.Tasks.TaskCanceledException: A task was canceled.
   --- End of inner exception stack trace ---
   at System.Threading.Tasks.Task.ThrowIfExceptional(Boolean includeTaskCanceledExceptions)
   at System.Threading.Tasks.Task`1.GetResultCore(Boolean waitCompletionNotification)
   at System.Threading.Tasks.Task`1.get_Result()
   at HBL_MLDV_APP.Repository.UniversalRepository.<GetData>d__11.MoveNext() in E:\Naveel\GIT_PROJECTS\HBL_MLDV_APP\HBL_MLDV_APP\Repository\UniversalRepository.cs:line 88
---> (Inner Exception #0) System.Threading.Tasks.TaskCanceledException: A task was canceled.<---
<---

------------------------------
8/25/2021 3:30:46 PM
Edit
------------------------------
System.AggregateException: One or more errors occurred. ---> System.AggregateException: One or more errors occurred. ---> System.Threading.Tasks.TaskCanceledException: A task was canceled.
   --- End of inner exception stack trace ---
   at System.Threading.Tasks.Task.ThrowIfExceptional(Boolean includeTaskCanceledExceptions)
   at System.Threading.Tasks.Task`1.GetResultCore(Boolean waitCompletionNotification)
   at System.Threading.Tasks.Task`1.get_Result()
   at HBL_MLDV_APP.Repository.UniversalRepository.<GetData>d__11.MoveNext() in E:\Naveel\GIT_PROJECTS\HBL_MLDV_APP\HBL_MLDV_APP\Repository\UniversalRepository.cs:line 88
   --- End of inner exception stack trace ---
   at System.Threading.Tasks.Task.ThrowIfExceptional(Boolean includeTaskCanceledExceptions)
   at System.Threading.Tasks.Task`1.GetResultCore(Boolean waitCompletionNotification)
   at System.Threading.Tasks.Task`1.get_Result()
   at HBL_MLDV_APP.Areas.UserManagement.Controllers.UserController.<GetUserAprvById>d__20.MoveNext() in E:\Naveel\GIT_PROJECTS\HBL_MLDV_APP\HBL_MLDV_APP\Areas\UserManagement\Controllers\UserController.cs:line 674
--- End of stack trace from previous location where exception was thrown ---
   at System.Runtime.CompilerServices.TaskAwaiter.ThrowForNonSuccess(Task task)
   at System.Runtime.CompilerServices.TaskAwaiter.HandleNonSuccessAndDebuggerNotification(Task task)
   at System.Runtime.CompilerServices.TaskAwaiter`1.GetResult()
   at HBL_MLDV_APP.Areas.UserManagement.Controllers.UserController.<Edit>d__8.MoveNext() in E:\Naveel\GIT_PROJECTS\HBL_MLDV_APP\HBL_MLDV_APP\Areas\UserManagement\Controllers\UserController.cs:line 243
---> (Inner Exception #0) System.AggregateException: One or more errors occurred. ---> System.Threading.Tasks.TaskCanceledException: A task was canceled.
   --- End of inner exception stack trace ---
   at System.Threading.Tasks.Task.ThrowIfExceptional(Boolean includeTaskCanceledExceptions)
   at System.Threading.Tasks.Task`1.GetResultCore(Boolean waitCompletionNotification)
   at System.Threading.Tasks.Task`1.get_Result()
   at HBL_MLDV_APP.Repository.UniversalRepository.<GetData>d__11.MoveNext() in E:\Naveel\GIT_PROJECTS\HBL_MLDV_APP\HBL_MLDV_APP\Repository\UniversalRepository.cs:line 88
---> (Inner Exception #0) System.Threading.Tasks.TaskCanceledException: A task was canceled.<---
<---

------------------------------
8/25/2021 4:05:42 PM
Edit
------------------------------
System.AggregateException: One or more errors occurred. ---> System.AggregateException: One or more errors occurred. ---> System.Threading.Tasks.TaskCanceledException: A task was canceled.
   --- End of inner exception stack trace ---
   at System.Threading.Tasks.Task.ThrowIfExceptional(Boolean includeTaskCanceledExceptions)
   at System.Threading.Tasks.Task`1.GetResultCore(Boolean waitCompletionNotification)
   at System.Threading.Tasks.Task`1.get_Result()
   at HBL_MLDV_APP.Repository.UniversalRepository.<GetData>d__11.MoveNext() in E:\Naveel\GIT_PROJECTS\HBL_MLDV_APP\HBL_MLDV_APP\Repository\UniversalRepository.cs:line 88
   --- End of inner exception stack trace ---
   at System.Threading.Tasks.Task.ThrowIfExceptional(Boolean includeTaskCanceledExceptions)
   at System.Threading.Tasks.Task`1.GetResultCore(Boolean waitCompletionNotification)
   at System.Threading.Tasks.Task`1.get_Result()
   at HBL_MLDV_APP.Areas.UserManagement.Controllers.UserController.<GetUserAprvById>d__20.MoveNext() in E:\Naveel\GIT_PROJECTS\HBL_MLDV_APP\HBL_MLDV_APP\Areas\UserManagement\Controllers\UserController.cs:line 674
--- End of stack trace from previous location where exception was thrown ---
   at System.Runtime.CompilerServices.TaskAwaiter.ThrowForNonSuccess(Task task)
   at System.Runtime.CompilerServices.TaskAwaiter.HandleNonSuccessAndDebuggerNotification(Task task)
   at System.Runtime.CompilerServices.TaskAwaiter`1.GetResult()
   at HBL_MLDV_APP.Areas.UserManagement.Controllers.UserController.<Edit>d__8.MoveNext() in E:\Naveel\GIT_PROJECTS\HBL_MLDV_APP\HBL_MLDV_APP\Areas\UserManagement\Controllers\UserController.cs:line 243
---> (Inner Exception #0) System.AggregateException: One or more errors occurred. ---> System.Threading.Tasks.TaskCanceledException: A task was canceled.
   --- End of inner exception stack trace ---
   at System.Threading.Tasks.Task.ThrowIfExceptional(Boolean includeTaskCanceledExceptions)
   at System.Threading.Tasks.Task`1.GetResultCore(Boolean waitCompletionNotification)
   at System.Threading.Tasks.Task`1.get_Result()
   at HBL_MLDV_APP.Repository.UniversalRepository.<GetData>d__11.MoveNext() in E:\Naveel\GIT_PROJECTS\HBL_MLDV_APP\HBL_MLDV_APP\Repository\UniversalRepository.cs:line 88
---> (Inner Exception #0) System.Threading.Tasks.TaskCanceledException: A task was canceled.<---
<---

------------------------------
8/25/2021 4:32:30 PM
Edit
------------------------------
System.AggregateException: One or more errors occurred. ---> System.AggregateException: One or more errors occurred. ---> System.Threading.Tasks.TaskCanceledException: A task was canceled.
   --- End of inner exception stack trace ---
   at System.Threading.Tasks.Task.ThrowIfExceptional(Boolean includeTaskCanceledExceptions)
   at System.Threading.Tasks.Task`1.GetResultCore(Boolean waitCompletionNotification)
   at System.Threading.Tasks.Task`1.get_Result()
   at HBL_MLDV_APP.Repository.UniversalRepository.<GetData>d__11.MoveNext()
   --- End of inner exception stack trace ---
   at System.Threading.Tasks.Task.ThrowIfExceptional(Boolean includeTaskCanceledExceptions)
   at System.Threading.Tasks.Task`1.GetResultCore(Boolean waitCompletionNotification)
   at System.Threading.Tasks.Task`1.get_Result()
   at HBL_MLDV_APP.Areas.UserManagement.Controllers.UserController.<GetUserAprvById>d__20.MoveNext()
--- End of stack trace from previous location where exception was thrown ---
   at System.Runtime.CompilerServices.TaskAwaiter.ThrowForNonSuccess(Task task)
   at System.Runtime.CompilerServices.TaskAwaiter.HandleNonSuccessAndDebuggerNotification(Task task)
   at System.Runtime.CompilerServices.TaskAwaiter`1.GetResult()
   at HBL_MLDV_APP.Areas.UserManagement.Controllers.UserController.<Edit>d__8.MoveNext()
---> (Inner Exception #0) System.AggregateException: One or more errors occurred. ---> System.Threading.Tasks.TaskCanceledException: A task was canceled.
   --- End of inner exception stack trace ---
   at System.Threading.Tasks.Task.ThrowIfExceptional(Boolean includeTaskCanceledExceptions)
   at System.Threading.Tasks.Task`1.GetResultCore(Boolean waitCompletionNotification)
   at System.Threading.Tasks.Task`1.get_Result()
   at HBL_MLDV_APP.Repository.UniversalRepository.<GetData>d__11.MoveNext()
---> (Inner Exception #0) System.Threading.Tasks.TaskCanceledException: A task was canceled.<---
<---

------------------------------
8/25/2021 5:35:18 PM
Edit
------------------------------
System.FormatException: The input is not a valid Base-64 string as it contains a non-base 64 character, more than two padding characters, or an illegal character among the padding characters. 
   at System.Convert.FromBase64_Decode(Char* startInputPtr, Int32 inputLength, Byte* startDestPtr, Int32 destLength)
   at System.Convert.FromBase64CharPtr(Char* inputPtr, Int32 inputLength)
   at System.Convert.FromBase64String(String s)
   at HBL_MLDV_APP.App_Start.EncryptDecrypt.Decrypt(String cipherText)
   at HBL_MLDV_APP.Areas.UserManagement.Controllers.UserController.<Edit>d__8.MoveNext()
------------------------------
8/25/2021 5:37:45 PM
Edit
------------------------------
System.NullReferenceException: Object reference not set to an instance of an object.
   at HBL_MLDV_APP.Areas.UserManagement.Controllers.UserController.<Edit>d__8.MoveNext()
------------------------------
8/25/2021 5:51:00 PM
Edit
------------------------------
System.FormatException: The input is not a valid Base-64 string as it contains a non-base 64 character, more than two padding characters, or an illegal character among the padding characters. 
   at System.Convert.FromBase64_Decode(Char* startInputPtr, Int32 inputLength, Byte* startDestPtr, Int32 destLength)
   at System.Convert.FromBase64CharPtr(Char* inputPtr, Int32 inputLength)
   at System.Convert.FromBase64String(String s)
   at HBL_MLDV_APP.App_Start.EncryptDecrypt.Decrypt(String cipherText)
   at HBL_MLDV_APP.Areas.UserManagement.Controllers.UserController.<Edit>d__8.MoveNext()
------------------------------
